<?xml version="1.0" ?>
<robot name="independent_robot" xmlns:xacro="http://ros.org/wiki/xacro">

  <xacro:property name="base_radius" value="0.14"/>
  <xacro:property name="base_length" value="0.18"/>
  <xacro:property name="base_mass"   value="2.5"/>

  <xacro:property name="wheel_radius" value="0.035"/>
  <xacro:property name="wheel_length" value="0.02"/>
  <xacro:property name="wheel_mass"   value="0.2"/>
  <xacro:property name="wheel_track"  value="0.23"/>

  <link name="base_link">
    <visual>
      <origin xyz="0 0 ${base_length/2}" rpy="0 0 3.14159"/>
      <geometry>
        <cylinder radius="${base_radius}" length="${base_length}"/>
      </geometry>
      <material name="dark_grey">
        <color rgba="0.2 0.2 0.2 1.0"/>
      </material>
    </visual>
    <collision>
      <origin xyz="0 0 ${base_length/2}" rpy="0 0 0"/>
      <geometry>
        <cylinder radius="${base_radius}" length="${base_length}"/>
      </geometry>
    </collision>
    <inertial>
      <origin xyz="0 0 ${base_length/2}" rpy="0 0 0"/>
      <mass value="${base_mass}"/>
      <inertia ixx="0.0189" ixy="0.0" ixz="0.0" iyy="0.0189" iyz="0.0" izz="0.0245"/>
    </inertial>
  </link>

  <link name="drive_left_wheel">
    <visual>
      <geometry>
        <cylinder radius="${wheel_radius}" length="${wheel_length}"/>
      </geometry>
    </visual>
    <collision>
      <geometry>
        <cylinder radius="${wheel_radius}" length="${wheel_length}"/>
      </geometry>
    </collision>
    <inertial>
    <mass value="${wheel_mass}"/>
    <inertia ixx="0.000067" ixy="0.0" ixz="0.0"
            iyy="0.000067" iyz="0.0"
            izz="0.00012"/>
    </inertial>
  </link>
  <joint name="drive_left_wheel_joint" type="continuous">
    <parent link="base_link"/>
    <child link="drive_left_wheel"/>
    <origin xyz="0 ${wheel_track/2} 0" rpy="-1.5708 0 0"/>
    <axis xyz="0 0 1"/>
  </joint>


  <link name="drive_right_wheel">
    <visual>
      <geometry>
        <cylinder radius="${wheel_radius}" length="${wheel_length}"/>
      </geometry>
    </visual>
    <collision>
      <geometry>
        <cylinder radius="${wheel_radius}" length="${wheel_length}"/>
      </geometry>
    </collision>
    <inertial>
      <mass value="${wheel_mass}"/>
      <inertia ixx="0.000067" ixy="0.0" ixz="0.0"
              iyy="0.000067" iyz="0.0"
              izz="0.00012"/>
    </inertial>
  </link>

  <joint name="drive_right_wheel_joint" type="continuous">
    <parent link="base_link"/>
    <child link="drive_right_wheel"/>
    <origin xyz="0 -${wheel_track/2} 0" rpy="-1.5708 0 0"/>
    <axis xyz="0 0 1"/>
  </joint>

  <link name="caster_wheel">
    <visual>
      <geometry>
        <sphere radius="${wheel_radius}"/>
      </geometry>
      <material name="light_grey">
        <color rgba="0.6 0.6 0.6 1.0"/>
      </material>
    </visual>
    <collision>
      <geometry>
        <sphere radius="${wheel_radius}"/>
      </geometry>
    </collision>
    <inertial>
      <mass value="0.1"/>
      <inertia ixx="0.00004" ixy="0.0" ixz="0.0" iyy="0.00004" iyz="0.0" izz="0.00004"/>
    </inertial>
  </link>

  <joint name="caster_joint" type="fixed">
    <parent link="base_link"/>
    <child link="caster_wheel"/>
    <origin xyz="0.09 0 0" rpy="0 0 0"/>
  </joint>

  <link name="front_caster">
    <visual>
      <geometry>
        <sphere radius="${wheel_radius}"/>
      </geometry>
      <material name="light_grey">
        <color rgba="0.6 0.6 0.6 1.0"/>
      </material>
    </visual>
    <collision>
      <geometry>
        <sphere radius="${wheel_radius}"/>
      </geometry>
    </collision>
    <inertial>
      <mass value="0.1"/>
      <inertia ixx="0.00004" ixy="0.0" ixz="0.0" iyy="0.00004" iyz="0.0" izz="0.00004"/>
    </inertial>
  </link>

  <joint name="front_caster_joint" type="fixed">
    <parent link="base_link"/>
    <child link="front_caster"/>
    <origin xyz="-0.09 0 0" rpy="0 0 0"/>
  </joint>

  <link name="laser_frame">
    <visual>
      <geometry>
        <cylinder radius="0.03" length="0.02"/>
      </geometry>
      <material name="blue">
        <color rgba="0.0 0.0 0.8 1.0"/>
      </material>
    </visual>
  </link>

  <joint name="laser_joint" type="fixed">
    <parent link="base_link"/>
    <child link="laser_frame"/>
    <origin xyz="0 0 ${base_length + 0.01}" rpy="0 0 0"/>
  </joint>

  <gazebo reference="caster_wheel">
    <mu1>1.0</mu1>
    <mu2>1.0</mu2>
    <kp>1000000.0</kp>
    <kd>10.0</kd>
  </gazebo>

  <gazebo reference="front_caster">
    <mu1>1.0</mu1>
    <mu2>1.0</mu2>
    <kp>1000000.0</kp>
    <kd>10.0</kd>
  </gazebo>

  <gazebo reference="drive_left_wheel">
    <mu1>1.0</mu1>
    <mu2>1.0</mu2>
    <kp>1000000.0</kp>
    <kd>10.0</kd>
  </gazebo>

  <gazebo reference="drive_right_wheel">
    <mu1>1.0</mu1>
    <mu2>1.0</mu2>
    <kp>1000000.0</kp>
    <kd>10.0</kd>
  </gazebo>

  <gazebo>
    <plugin filename="gz-sim-diff-drive-system" name="gz::sim::systems::DiffDrive">
      <left_joint>drive_left_wheel_joint</left_joint>
      <right_joint>drive_right_wheel_joint</right_joint>
      <wheel_separation>${wheel_track}</wheel_separation>
      <wheel_radius>${wheel_radius}</wheel_radius>
      <topic>cmd_vel</topic>
    </plugin>

    <plugin filename="gz-sim-odometry-publisher-system" name="gz::sim::systems::OdometryPublisher">
      <odom_frame>odom</odom_frame>
      <robot_base_frame>base_link</robot_base_frame>
      <odom_publish_frequency>50</odom_publish_frequency>
      <odom_topic>/odom</odom_topic>
      <tf_topic>/tf</tf_topic>
      <dimensions>2</dimensions>
    </plugin>
  </gazebo>

  <gazebo>
    <plugin filename="gz-sim-joint-state-publisher-system" name="gz::sim::systems::JointStatePublisher">
      <topic>joint_states</topic>
    </plugin>
  </gazebo>

  <gazebo reference="laser_frame">
    <sensor name="gpu_lidar" type="gpu_lidar">
      <pose>0 0 0 0 0 0</pose>
      <update_rate>10</update_rate>
      <visualize>true</visualize>
      <topic>scan</topic>
      <gz_frame_id>laser_frame</gz_frame_id>
      <lidar>
        <scan>
          <horizontal>
            <samples>640</samples>
            <resolution>1</resolution>
            <min_angle>-3.141592</min_angle>
            <max_angle>3.141592</max_angle>
          </horizontal>
        </scan>
        <range>
          <min>0.08</min>
          <max>10.0</max>
        </range>
      </lidar>
      </sensor>
  </gazebo>

</robot>
